Workbook

Sheet storage capacity
A1: Country | B1: Continent | C1: Grouping | G1: Grouping | L1: Country | N1: storage capacity | Q1: Group / countries | T1: Storage capacity | U1: Latitude | V1: Longitude
A2: Afghanistan | B2: Asia | C2: Middle east | G2: North africa | H2: =COUNTIF($C$2:$C$195,G2) -> 0 | L2: Afghanistan | M2: =VLOOKUP(L2,$A$2:$C$195,3,FALSE) -> Middle east | N2: 0 | Q2: Sub-saharan africa | T2: =SUMIF($M$2:$M$196,Q2,$N$2:$N$196) -> 223.03 | U2: -4.2694 | V2: 15.2712
A3: Albania | B3: Europe | C3: Other eurasia | G3: Sub-saharan africa | H3: =COUNTIF($C$2:$C$195,G3) -> 49 | L3: Albania | M3: =VLOOKUP(L3,$A$2:$C$195,3,FALSE) -> Other eurasia | N3: 3.711 | Q3: Other eurasia | T3: =SUMIF($M$2:$M$196,Q3,$N$2:$N$196) -> 1043.6532 | U3: 39.9208 | V3: 32.854
A4: Algeria | B4: Africa | C4: Middle east | G4: Other eurasia | H4: =COUNTIF($C$2:$C$195,G4) -> 36 | L4: Algeria | M4: =VLOOKUP(L4,$A$2:$C$195,3,FALSE) -> Middle east | N4: 10 | Q4: Other latin america | T4: =SUMIF($M$2:$M$196,Q4,$N$2:$N$196) -> 1.02337 | U4: 4.6534 | V4: -74.0837
A5: Andorra | B5: Europe | C5: Other eurasia | G5: Other latin america | H5: =COUNTIF($C$2:$C$195,G5) -> 28 | L5: Andorra | M5: =VLOOKUP(L5,$A$2:$C$195,3,FALSE) -> Other eurasia | N5: 0 | Q5: Middle east | T5: =SUMIF($M$2:$M$196,Q5,$N$2:$N$196) -> 260.70909 | U5: 30.0444 | V5: 31.2357
A6: Angola | B6: Africa | C6: Sub-saharan africa | G6: Middle east | H6: =COUNTIF($C$2:$C$195,G6) -> 18 | L6: Angola | M6: =VLOOKUP(L6,$A$2:$C$195,3,FALSE) -> Sub-saharan africa | N6: 0 | Q6: Other Asia pacific | T6: =SUMIF($M$2:$M$196,Q6,$N$2:$N$196) -> 85.24221 | U6: 1.3571 | V6: 103.8195
A7: Antigua & Barbuda | B7: N. America | C7: Other latin america | G7: Other Asia pacific | H7: =COUNTIF($C$2:$C$195,G7) -> 19 | L7: Antigua & Barbuda | M7: =VLOOKUP(L7,$A$2:$C$195,3,FALSE) -> Other latin america | N7: 0 | Q7: {=_xlfn._xlws.FILTER(A2:C195,C2:C195=G8)} -> Argentina | R7: S. America | S7: Country specific | T7: =VLOOKUP(Q7,$L$2:$N$196,3,FALSE) -> 2.7 | U7: =VLOOKUP(Q7,'lat lon'!$A$2:$E$195,4,FALSE) -> -34.6084 | V7: =VLOOKUP(Q7,'lat lon'!$A$2:$E$195,5,FALSE) -> -58.4441
A8: Argentina | B8: S. America | C8: Country specific | G8: Country specific | H8: =COUNTIF($C$2:$C$195,G8) -> 35 | L8: Argentina | M8: =VLOOKUP(L8,$A$2:$C$195,3,FALSE) -> Country specific | N8: 2.7 | Q8: Australia | R8: Australia | S8: Country specific | T8: =VLOOKUP(Q8,$L$2:$N$196,3,FALSE) -> 2984.5 | U8: =VLOOKUP(Q8,'lat lon'!$A$2:$E$195,4,FALSE) -> -35.293056 | V8: =VLOOKUP(Q8,'lat lon'!$A$2:$E$195,5,FALSE) -> 149.12694
A9: Armenia | B9: Asia | C9: Other eurasia | G9: Oceania | H9: =COUNTIF($C$2:$C$195,G9) -> 9 | L9: Armenia | M9: =VLOOKUP(L9,$A$2:$C$195,3,FALSE) -> Other eurasia | N9: 0 | Q9: Belgium | R9: Europe | S9: Country specific | T9: =VLOOKUP(Q9,$L$2:$N$196,3,FALSE) -> 0.199 | U9: =VLOOKUP(Q9,'lat lon'!$A$2:$E$195,4,FALSE) -> 50.846667 | V9: =VLOOKUP(Q9,'lat lon'!$A$2:$E$195,5,FALSE) -> 4.3516667
A10: Australia | B10: Australia | C10: Country specific | L10: Australia | M10: =VLOOKUP(L10,$A$2:$C$195,3,FALSE) -> Country specific | N10: 2984.5 | Q10: Brazil | R10: S. America | S10: Country specific | T10: =VLOOKUP(Q10,$L$2:$N$196,3,FALSE) -> 1489 | U10: =VLOOKUP(Q10,'lat lon'!$A$2:$E$195,4,FALSE) -> -15.793889 | V10: =VLOOKUP(Q10,'lat lon'!$A$2:$E$195,5,FALSE) -> -47.882778
A11: Austria | B11: Europe | C11: Other eurasia | L11: Austria | M11: =VLOOKUP(L11,$A$2:$C$195,3,FALSE) -> Other eurasia | N11: 0.146 | Q11: Canada | R11: N. America | S11: Country specific | T11: =VLOOKUP(Q11,$L$2:$N$196,3,FALSE) -> 1595 | U11: =VLOOKUP(Q11,'lat lon'!$A$2:$E$195,4,FALSE) -> 45.424722 | V11: =VLOOKUP(Q11,'lat lon'!$A$2:$E$195,5,FALSE) -> -75.695
A12: Azerbaijan | B12: Asia | C12: Other eurasia | L12: Azerbaijan | M12: =VLOOKUP(L12,$A$2:$C$195,3,FALSE) -> Other eurasia | N12: 0 | Q12: China | R12: Asia | S12: Country specific | T12: =VLOOKUP(Q12,$L$2:$N$196,3,FALSE) -> 2019.5 | U12: =VLOOKUP(Q12,'lat lon'!$A$2:$E$195,4,FALSE) -> 40.1906 | V12: =VLOOKUP(Q12,'lat lon'!$A$2:$E$195,5,FALSE) -> 116.4121
A13: Bahamas | B13: N. America | C13: Other latin america | L13: Bahamas | M13: =VLOOKUP(L13,$A$2:$C$195,3,FALSE) -> Other latin america | N13: 0 | Q13: Denmark | R13: Europe | S13: Country specific | T13: =VLOOKUP(Q13,$L$2:$N$196,3,FALSE) -> 16.02794 | U13: =VLOOKUP(Q13,'lat lon'!$A$2:$E$195,4,FALSE) -> 55.676111 | V13: =VLOOKUP(Q13,'lat lon'!$A$2:$E$195,5,FALSE) -> 12.568889
A14: Bahrain | B14: Asia | C14: Middle east | L14: Bahrain | M14: =VLOOKUP(L14,$A$2:$C$195,3,FALSE) -> Middle east | N14: 0 | Q14: Egypt | R14: Africa | S14: Country specific | T14: =VLOOKUP(Q14,$L$2:$N$196,3,FALSE) -> 667.17 | U14: =VLOOKUP(Q14,'lat lon'!$A$2:$E$195,4,FALSE) -> 30.044444 | V14: =VLOOKUP(Q14,'lat lon'!$A$2:$E$195,5,FALSE) -> 31.235833
A15: Bangladesh | B15: Asia | C15: Other Asia pacific | L15: Bangladesh | M15: =VLOOKUP(L15,$A$2:$C$195,3,FALSE) -> Other Asia pacific | N15: 21.133 | Q15: Finland | R15: Europe | S15: Country specific | T15: =VLOOKUP(Q15,$L$2:$N$196,3,FALSE) -> 2 | U15: =VLOOKUP(Q15,'lat lon'!$A$2:$E$195,4,FALSE) -> 60.170833 | V15: =VLOOKUP(Q15,'lat lon'!$A$2:$E$195,5,FALSE) -> 24.9375
A16: Barbados | B16: N. America | C16: Other latin america | L16: Barbados | M16: =VLOOKUP(L16,$A$2:$C$195,3,FALSE) -> Other latin america | N16: 0 | Q16: France | R16: Europe | S16: Country specific | T16: =VLOOKUP(Q16,$L$2:$N$196,3,FALSE) -> 7.207851 | U16: =VLOOKUP(Q16,'lat lon'!$A$2:$E$195,4,FALSE) -> 48.856667 | V16: =VLOOKUP(Q16,'lat lon'!$A$2:$E$195,5,FALSE) -> 2.3522222
A17: Belarus | B17: Europe | C17: Other eurasia | L17: Belarus | M17: =VLOOKUP(L17,$A$2:$C$195,3,FALSE) -> Other eurasia | N17: 0 | Q17: Germany | R17: Europe | S17: Country specific | T17: =VLOOKUP(Q17,$L$2:$N$196,3,FALSE) -> 51.2076 | U17: =VLOOKUP(Q17,'lat lon'!$A$2:$E$195,4,FALSE) -> 52.5109 | V17: =VLOOKUP(Q17,'lat lon'!$A$2:$E$195,5,FALSE) -> 13.3989
A18: Belgium | B18: Europe | C18: Country specific | L18: Belgium | M18: =VLOOKUP(L18,$A$2:$C$195,3,FALSE) -> Country specific | N18: 0.199 | Q18: Iceland | R18: Europe | S18: Country specific | T18: =VLOOKUP(Q18,$L$2:$N$196,3,FALSE) -> 0 | U18: =VLOOKUP(Q18,'lat lon'!$A$2:$E$195,4,FALSE) -> 64.1475 | V18: =VLOOKUP(Q18,'lat lon'!$A$2:$E$195,5,FALSE) -> -21.935
A19: Belize | B19: N. America | C19: Other latin america | L19: Belize | M19: =VLOOKUP(L19,$A$2:$C$195,3,FALSE) -> Other latin america | N19: 0 | Q19: India | R19: Asia | S19: Country specific | T19: =VLOOKUP(Q19,$L$2:$N$196,3,FALSE) -> 497 | U19: =VLOOKUP(Q19,'lat lon'!$A$2:$E$195,4,FALSE) -> 28.613895 | V19: =VLOOKUP(Q19,'lat lon'!$A$2:$E$195,5,FALSE) -> 77.209006
A20: Benin | B20: Africa | C20: Sub-saharan africa | L20: Benin | M20: =VLOOKUP(L20,$A$2:$C$195,3,FALSE) -> Sub-saharan africa | N20: 0 | Q20: Indonesia | R20: Asia | S20: Country specific | T20: =VLOOKUP(Q20,$L$2:$N$196,3,FALSE) -> 653.5 | U20: =VLOOKUP(Q20,'lat lon'!$A$2:$E$195,4,FALSE) -> -6.1754 | V20: =VLOOKUP(Q20,'lat lon'!$A$2:$E$195,5,FALSE) -> 106.8272
A21: Bhutan | B21: Asia | C21: Other Asia pacific | L21: Bhutan | M21: =VLOOKUP(L21,$A$2:$C$195,3,FALSE) -> Other Asia pacific | N21: 0 | Q21: Iran | R21: Asia | S21: Country specific | T21: =VLOOKUP(Q21,$L$2:$N$196,3,FALSE) -> 117.6264 | U21: =VLOOKUP(Q21,'lat lon'!$A$2:$E$195,4,FALSE) -> 35.688889 | V21: =VLOOKUP(Q21,'lat lon'!$A$2:$E$195,5,FALSE) -> 51.389722
... A41: Costa Rica | B41: N. America | C41: Other latin america | L41: Costa Rica | M41: =VLOOKUP(L41,$A$2:$C$195,3,FALSE) -> Other latin america | N41: 0 | Q41: United States | R41: N. America | S41: Country specific | T41: =VLOOKUP(Q41,$L$2:$N$196,3,FALSE) -> 3050 | U41: =VLOOKUP(Q41,'lat lon'!$A$2:$E$195,4,FALSE) -> 38.895 | V41: =VLOOKUP(Q41,'lat lon'!$A$2:$E$195,5,FALSE) -> -77.0365
A42: Côte d'Ivoire | B42: Africa | C42: Sub-saharan africa | L42: Côte d'Ivoire | M42: =VLOOKUP(L42,$A$2:$C$195,3,FALSE) -> Sub-saharan africa | N42: 0
A43: Croatia | B43: Europe | C43: Other eurasia | L43: Croatia | M43: =VLOOKUP(L43,$A$2:$C$195,3,FALSE) -> Other eurasia | N43: 4.89685
A44: Cuba | B44: N. America | C44: Other latin america | L44: Cuba | M44: =VLOOKUP(L44,$A$2:$C$195,3,FALSE) -> Other latin america | N44: 0
A45: Cyprus | B45: Asia | C45: Other eurasia | L45: Cyprus | M45: =VLOOKUP(L45,$A$2:$C$195,3,FALSE) -> Other eurasia | N45: 0
A46: Czech Republic | B46: Europe | C46: Other eurasia | L46: Czech Republic | M46: =VLOOKUP(L46,$A$2:$C$195,3,FALSE) -> Other eurasia | N46: 0.49179494
A47: Denmark | B47: Europe | C47: Country specific | L47: Denmark | M47: =VLOOKUP(L47,$A$2:$C$195,3,FALSE) -> Country specific | N47: 16.02794
A48: Djibouti | B48: Africa | C48: Sub-saharan africa | L48: Djibouti | M48: =VLOOKUP(L48,$A$2:$C$195,3,FALSE) -> Sub-saharan africa | N48: 0
A49: Dominica | B49: N. America | C49: Sub-saharan africa | L49: Dominica | M49: =VLOOKUP(L49,$A$2:$C$195,3,FALSE) -> Sub-saharan africa | N49: 0
A50: Dominican Republic | B50: N. America | C50: Sub-saharan africa | L50: Dominican Republic | M50: =VLOOKUP(L50,$A$2:$C$195,3,FALSE) -> Sub-saharan africa | N50: 0
A51: DR Congo | B51: Africa | C51: Sub-saharan africa | L51: DR Congo | M51: =VLOOKUP(L51,$A$2:$C$195,3,FALSE) -> Sub-saharan africa | N51: 0
A52: Ecuador | B52: S. America | C52: Other latin america | L52: Ecuador | M52: =VLOOKUP(L52,$A$2:$C$195,3,FALSE) -> Other latin america | N52: 0
A53: Egypt | B53: Africa | C53: Country specific | L53: Egypt | M53: =VLOOKUP(L53,$A$2:$C$195,3,FALSE) -> Country specific | N53: 667.17
... A195: Zimbabwe | B195: Africa | C195: Sub-saharan africa | L195: Zambia | M195: =VLOOKUP(L195,$A$2:$C$195,3,FALSE) -> Sub-saharan africa | N195: 0
L196: Zimbabwe | M196: =VLOOKUP(L196,$A$2:$C$195,3,FALSE) -> Sub-saharan africa | N196: 0

Sheet GDP
A1: Country | C1: =[1]cost_table!B1 -> 2030 | D1: =[1]cost_table!C1 -> 2031 | E1: =[1]cost_table!D1 -> 2032 | F1: =[1]cost_table!E1 -> 2033 | G1: =[1]cost_table!F1 -> 2034 | H1: =[1]cost_table!G1 -> 2035 | I1: =[1]cost_table!H1 -> 2036 | J1: =[1]cost_table!I1 -> 2037 | ... BU1: =[1]cost_table!BT1 -> 2100
A2: Afghanistan | B2: =VLOOKUP(A2,'storage capacity'!$A$2:$C$195,3,FALSE) -> Middle east | C2: 17362.933 | D2: 17362.933 | E2: 17362.933 | F2: 17362.933 | G2: 17362.933 | H2: 17362.933 | I2: 17362.933 | J2: 17362.933 | K2: 17362.933 | L2: 17362.933 | M2: 17362.933 | N2: 17362.933 | O2: 17362.933 | P2: 17362.933 | Q2: 17362.933 | R2: 17362.933 | S2: 17362.933 | T2: 17362.933 | U2: 17362.933 | V2: 17362.933 | W2: 17362.933 | X2: 17362.933 | Y2: 17362.933 | Z2: 17362.933 | AA2: 17362.933 | AB2: 17362.933 | AC2: 17362.933 | AD2: 17362.933 | AE2: 17362.933 | AF2: 17362.933 | AG2: 17362.933 | AH2: 17362.933 | AI2: 17362.933 | AJ2: 17362.933 | AK2: 17362.933 | AL2: 17362.933 | AM2: 17362.933 | AN2: 17362.933 | AO2: 17362.933 | AP2: 17362.933 | AQ2: 17362.933 | AR2: 17362.933 | AS2: 17362.933 | AT2: 17362.933 | AU2: 17362.933 | AV2: 17362.933 | AW2: 17362.933 | AX2: 17362.933 | AY2: 17362.933 | AZ2: 17362.933 | BA2: 17362.933 | BB2: 17362.933 | BC2: 17362.933 | BD2: 17362.933 | BE2: 17362.933 | BF2: 17362.933 | BG2: 17362.933 | BH2: 17362.933 | BI2: 17362.933 | BJ2: 17362.933 | BK2: 17362.933 | BL2: 17362.933 | BM2: 17362.933 | BN2: 17362.933 | BO2: 17362.933 | BP2: 17362.933 | BQ2: 17362.933 | BR2: 17362.933 | BS2: 17362.933 | BT2: 17362.933 | BU2: 17362.933
A3: Albania | B3: =VLOOKUP(A3,'storage capacity'!$A$2:$C$195,3,FALSE) -> Other eurasia | C3: 39005.533 | D3: 41656.873 | E3: 44460.118 | F3: 47422.084 | G3: 50549.786 | H3: 53850.434 | I3: 57331.436 | J3: 61000.398 | K3: 64865.119 | L3: 68933.596 | M3: 73214.02 | N3: 77714.775 | O3: 82444.434 | P3: 87411.762 | Q3: 92625.708 | R3: 98095.407 | S3: 103830.17 | T3: 109839.5 | U3: 116133.05 | V3: 122720.67 | W3: 129612.36 | X3: 136818.28 | Y3: 144348.76 | Z3: 152214.26 | AA3: 160425.41 | AB3: 168992.96 | AC3: 177927.82 | AD3: 187241 | AE3: 196943.65 | AF3: 207047.03 | AG3: 217562.5 | AH3: 228501.54 | AI3: 239875.69 | AJ3: 251696.62 | AK3: 263976.05 | AL3: 276725.75 | AM3: 289957.6 | AN3: 303683.5 | AO3: 317915.39 | AP3: 332665.25 | AQ3: 347945.1 | AR3: 363766.97 | AS3: 380142.88 | AT3: 397084.86 | AU3: 414604.93 | AV3: 432715.08 | AW3: 451427.28 | AX3: 470753.46 | AY3: 490705.47 | AZ3: 511295.14 | BA3: 532534.2 | BB3: 554434.32 | BC3: 577007.05 | BD3: 600263.87 | BE3: 624216.14 | BF3: 648875.1 | BG3: 674251.84 | BH3: 700357.35 | BI3: 727202.45 | BJ3: 754797.79 | BK3: 783153.87 | BL3: 812281.01 | BM3: 842189.35 | BN3: 872888.83 | BO3: 904389.17 | BP3: 936699.92 | BQ3: 969830.36 | BR3: 1003789.6 | BS3: 1038586.4 | BT3: 1074229.5 | BU3: 1110727.1
A4: Algeria | B4: =VLOOKUP(A4,'storage capacity'!$A$2:$C$195,3,FALSE) -> Middle east | C4: 396513.13 | D4: 428620.81 | E4: 462981.33 | F4: 499725.23 | G4: 538988.65 | H4: 580913.52 | I4: 625647.63 | J4: 673344.77 | K4: 724164.82 | L4: 778273.92 | M4: 835844.5 | N4: 897055.39 | O4: 962091.98 | P4: 1031146.2 | Q4: 1104416.7 | R4: 1182108.8 | S4: 1264434.8 | T4: 1351613.5 | U4: 1443871.2 | V4: 1541440.5 | W4: 1644561.4 | X4: 1753480.8 | Y4: 1868452.6 | Z4: 1989737.8 | AA4: 2117604.2 | AB4: 2252327 | AC4: 2394187.8 | AD4: 2543475.7 | AE4: 2700486.4 | AF4: 2865522.4 | AG4: 3038893.1 | AH4: 3220914.6 | AI4: 3411909.4 | AJ4: 3612206.7 | AK4: 3822141.9 | AL4: 4042056.9 | AM4: 4272299.4 | AN4: 4513223.3 | AO4: 4765188.4 | AP4: 5028559.9 | AQ4: 5303708.7 | AR4: 5591010.7 | AS4: 5890847.3 | AT4: 6203604.5 | AU4: 6529672.9 | AV4: 6869447.9 | AW4: 7223328.6 | AX4: 7591718.4 | AY4: 7975024.4 | AZ4: 8373656.8 | BA4: 8788029.4 | BB4: 9218558.6 | BC4: 9665663.3 | BD4: 10129765 | BE4: 10611287 | BF4: 11110654 | BG4: 11628292 | BH4: 12164630 | BI4: 12720094 | BJ4: 13295114 | BK4: 13890118 | BL4: 14505535 | BM4: 15141791 | BN4: 15799313 | BO4: 16478527 | BP4: 17179857 | BQ4: 17903724 | BR4: 18650546 | BS4: 19420742 | BT4: 20214723 | BU4: 21032901
A5: Andorra | B5: =VLOOKUP(A5,'storage capacity'!$A$2:$C$195,3,FALSE) -> Other eurasia | C5: 4920.0667 | D5: 5094.8229 | E5: 5273.9767 | F5: 5457.5758 | G5: 5645.6664 | H5: 5838.2936 | I5: 6035.5012 | J5: 6237.3315 | K5: 6443.8253 | L5: 6655.0219 | M5: 6870.9594 | N5: 7091.674 | O5: 7317.2005 | P5: 7547.5722 | Q5: 7782.8205 | R5: 8022.9755 | S5: 8268.0652 | T5: 8518.1163 | U5: 8773.1536 | V5: 9033.2 | W5: 9298.2771 | X5: 9568.4042 | Y5: 9843.599 | Z5: 10123.878 | AA5: 10409.254 | AB5: 10699.741 | AC5: 10995.348 | AD5: 11296.084 | AE5: 11601.956 | AF5: 11912.969 | AG5: 12229.126 | AH5: 12550.427 | AI5: 12876.873 | AJ5: 13208.461 | AK5: 13545.186 | AL5: 13887.042 | AM5: 14234.021 | AN5: 14586.114 | AO5: 14943.307 | AP5: 15305.588 | AQ5: 15672.942 | AR5: 16045.351 | AS5: 16422.796 | AT5: 16805.257 | AU5: 17192.711 | AV5: 17585.134 | AW5: 17982.501 | AX5: 18384.783 | AY5: 18791.952 | AZ5: 19203.976 | BA5: 19620.824 | BB5: 20042.461 | BC5: 20468.852 | BD5: 20899.959 | BE5: 21335.744 | BF5: 21776.167 | BG5: 22221.187 | BH5: 22670.759 | BI5: 23124.841 | BJ5: 23583.386 | BK5: 24046.347 | BL5: 24513.675 | BM5: 24985.322 | BN5: 25461.237 | BO5: 25941.366 | BP5: 26425.658 | BQ5: 26914.058 | BR5: 27406.509 | BS5: 27902.957 | BT5: 28403.343 | BU5: 28907.609
A6: Angola | B6: =VLOOKUP(A6,'storage capacity'!$A$2:$C$195,3,FALSE) -> Sub-saharan africa | C6: 157107.07 | D6: 165344.92 | E6: 173928.03 | F6: 182866.4 | G6: 192170.14 | H6: 201849.47 | I6: 211914.66 | J6: 222376.07 | K6: 233244.15 | L6: 244529.39 | M6: 256242.34 | N6: 268393.59 | O6: 280993.8 | P6: 294053.63 | Q6: 307583.77 | R6: 321594.94 | S6: 336097.87 | T6: 351103.25 | U6: 366621.82 | V6: 382664.25 | W6: 399241.21 | X6: 416363.33 | Y6: 434041.2 | Z6: 452285.35 | AA6: 471106.25 | AB6: 490514.3 | AC6: 510519.83 | AD6: 531133.06 | AE6: 552364.13 | AF6: 574223.08 | AG6: 596719.82 | AH6: 619864.15 | AI6: 643665.74 | AJ6: 668134.11 | AK6: 693278.63 | AL6: 719108.54 | AM6: 745632.88 | AN6: 772860.55 | AO6: 800800.25 | AP6: 829460.49 | AQ6: 858849.62 | AR6: 888975.75 | AS6: 919846.78 | AT6: 951470.44 | AU6: 983854.18 | AV6: 1017005.3 | AW6: 1050930.7 | AX6: 1085637.2 | AY6: 1121131.4 | AZ6: 1157419.5 | BA6: 1194507.5 | BB6: 1232401.2 | BC6: 1271106.1 | BD6: 1310627.3 | BE6: 1350969.8 | BF6: 1392138.3 | BG6: 1434137 | BH6: 1476970.2 | BI6: 1520641.5 | BJ6: 1565154.4 | BK6: 1610512.2 | BL6: 1656717.8 | BM6: 1703773.6 | BN6: 1751682.1 | BO6: 1800445.2 | BP6: 1850064.5 | BQ6: 1900541.4 | BR6: 1951877 | BS6: 2004072 | BT6: 2057126.8 | BU6: 2111041.6
A7: Antigua & Barbuda | B7: =VLOOKUP(A7,'storage capacity'!$A$2:$C$195,3,FALSE) -> Other latin america | C7: 3193.0667 | D7: 3393.0513 | E7: 3603.436 | F7: 3824.6312 | G7: 4057.0567 | H7: 4301.1414 | I7: 4557.3232 | J7: 4826.0491 | K7: 5107.7749 | L7: 5402.9651 | M7: 5712.0925 | N7: 6035.6383 | O7: 6374.0917 | P7: 6727.9499 | Q7: 7097.7175 | R7: 7483.9066 | S7: 7887.0364 | T7: 8307.6328 | U7: 8746.2283 | V7: 9203.3616 | W7: 9679.5774 | X7: 10175.426 | Y7: 10691.462 | Z7: 11228.247 | AA7: 11786.344 | AB7: 12366.323 | AC7: 12968.756 | AD7: 13594.22 | AE7: 14243.292 | AF7: 14916.555 | AG7: 15614.591 | AH7: 16337.985 | AI7: 17087.324 | AJ7: 17863.193 | AK7: 18666.181 | AL7: 19496.875 | AM7: 20355.859 | AN7: 21243.72 | AO7: 22161.041 | AP7: 23108.404 | AQ7: 24086.386 | AR7: 25095.565 | AS7: 26136.512 | AT7: 27209.795 | AU7: 28315.979 | AV7: 29455.622 | AW7: 30629.277 | AX7: 31837.492 | AY7: 33080.808 | AZ7: 34359.759 | BA7: 35674.873 | BB7: 37026.668 | BC7: 38415.654 | BD7: 39842.336 | BE7: 41307.204 | BF7: 42810.744 | BG7: 44353.428 | BH7: 45935.72 | BI7: 47558.073 | BJ7: 49220.927 | BK7: 50924.712 | BL7: 52669.846 | BM7: 54456.735 | BN7: 56285.771 | BO7: 58157.334 | BP7: 60071.791 | BQ7: 62029.494 | BR7: 64030.782 | BS7: 66075.98 | BT7: 68165.399 | BU7: 70299.333
A8: Argentina | B8: =VLOOKUP(A8,'storage capacity'!$A$2:$C$195,3,FALSE) -> Country specific | C8: 741024.4 | D8: 769131.4 | E8: 798012.77 | F8: 827678.99 | G8: 858140.36 | H8: 889406.99 | I8: 921488.78 | J8: 954395.39 | K8: 988136.29 | L8: 1022720.7 | M8: 1058157.6 | N8: 1094455.7 | O8: 1131623.6 | P8: 1169669.4 | Q8: 1208601 | R8: 1248426.2 | S8: 1289152.3 | T8: 1330786.4 | U8: 1373335.3 | V8: 1416805.5 | W8: 1461203.3 | X8: 1506534.4 | Y8: 1552804.5 | Z8: 1600018.7 | AA8: 1648182.1 | AB8: 1697299.1 | AC8: 1747374 | AD8: 1798410.7 | AE8: 1850412.8 | AF8: 1903383.6 | AG8: 1957325.8 | AH8: 2012242.1 | AI8: 2068134.5 | AJ8: 2125005 | AK8: 2182855 | AL8: 2241685.7 | AM8: 2301497.7 | AN8: 2362291.5 | AO8: 2424067.2 | AP8: 2486824.5 | AQ8: 2550562.7 | AR8: 2615280.8 | AS8: 2680977.5 | AT8: 2747651 | AU8: 2815299.3 | AV8: 2883920 | AW8: 2953510.3 | AX8: 3024067.2 | AY8: 3095587.2 | AZ8: 3168066.6 | BA8: 3241501.2 | BB8: 3315886.6 | BC8: 3391218.1 | BD8: 3467490.6 | BE8: 3544698.6 | BF8: 3622836.6 | BG8: 3701898.3 | BH8: 3781877.6 | BI8: 3862767.7 | BJ8: 3944561.8 | BK8: 4027252.6 | BL8: 4110832.6 | BM8: 4195294.1 | BN8: 4280629 | BO8: 4366828.9 | BP8: 4453885.3 | BQ8: 4541789.3 | BR8: 4630531.8 | BS8: 4720103.5 | BT8: 4810494.8 | BU8: 4901696
A9: Armenia | B9: =VLOOKUP(A9,'storage capacity'!$A$2:$C$195,3,FALSE) -> Other eurasia | C9: 36339.333 | D9: 38810.574 | E9: 41423.477 | F9: 44184.404 | G9: 47099.901 | H9: 50176.698 | I9: 53421.709 | J9: 56842.03 | K9: 60444.945 | L9: 64237.917 | M9: 68228.591 | N9: 72424.793 | O9: 76834.527 | P9: 81465.975 | Q9: 86327.493 | R9: 91427.607 | S9: 96775.015 | T9: 102378.58 | U9: 108247.33 | V9: 114390.44 | W9: 120817.27 | X9: 127537.29 | Y9: 134560.16 | Z9: 141895.64 | AA9: 149553.67 | AB9: 157544.27 | AC9: 165877.64 | AD9: 174564.06 | AE9: 183613.95 | AF9: 193037.82 | AG9: 202846.28 | AH9: 213050.06 | AI9: 223659.94 | AJ9: 234686.82 | AK9: 246141.64 | AL9: 258035.41 | AM9: 270379.22 | AN9: 283184.19 | AO9: 296461.47 | AP9: 310222.27 | AQ9: 324477.81 | AR9: 339239.32 | AS9: 354518.05 | AT9: 370325.23 | AU9: 386672.11 | AV9: 403569.88 | AW9: 421029.73 | AX9: 439062.8 | AY9: 457680.2 | AZ9: 476892.94 | BA9: 496712.02 | BB9: 517148.33 | BC9: 538212.68 | BD9: 559915.8 | BE9: 582268.3 | BF9: 605280.69 | BG9: 628963.35 | BH9: 653326.55 | BI9: 678380.4 | BJ9: 704134.87 | BK9: 730599.77 | BL9: 757784.77 | BM9: 785699.33 | BN9: 814352.75 | BO9: 843754.14 | BP9: 873912.41 | BQ9: 904836.26 | BR9: 936534.19 | BS9: 969014.47 | BT9: 1002285.1 | BU9: 1036354
A10: Australia | B10: =VLOOKUP(A10,'storage capacity'!$A$2:$C$195,3,FALSE) -> Country specific | C10: 2295761.2 | D10: 2395576.7 | E10: 2498690.4 | F10: 2605166.9 | G10: 2715070.6 | H10: 2828465.4 | I10: 2945414.8 | J10: 3065981.9 | K10: 3190229.2 | L10: 3318218.8 | M10: 3450012 | N10: 3585669.4 | O10: 3725251.2 | P10: 3868816.3 | Q10: 4016423.2 | R10: 4168129.5 | S10: 4323991.5 | T10: 4484064.8 | U10: 4648404.1 | V10: 4817062.7 | W10: 4990093 | X10: 5167546.1 | Y10: 5349472.1 | Z10: 5535919.5 | AA10: 5726935.7 | AB10: 5922566.9 | AC10: 6122857.7 | AD10: 6327851.4 | AE10: 6537589.6 | AF10: 6752112.8 | AG10: 6971459.7 | AH10: 7195667.5 | AI10: 7424771.8 | AJ10: 7658806.6 | AK10: 7897804.3 | AL10: 8141795.5 | AM10: 8390809.1 | AN10: 8644872.5 | AO10: 8904011 | AP10: 9168248.3 | AQ10: 9437606.5 | AR10: 9712105.5 | AS10: 9991763.7 | AT10: 10276597 | AU10: 10566621 | AV10: 10861848 | AW10: 11162289 | AX10: 11467952 | AY10: 11778845 | AZ10: 12094973 | BA10: 12416340 | BB10: 12742946 | BC10: 13074792 | BD10: 13411874 | BE10: 13754189 | BF10: 14101731 | BG10: 14454490 | BH10: 14812459 | BI10: 15175624 | BJ10: 15543973 | BK10: 15917489 | BL10: 16296156 | BM10: 16679955 | BN10: 17068864 | BO10: 17462861 | BP10: 17861922 | BQ10: 18266020 | BR10: 18675128 | BS10: 19089216 | BT10: 19508253 | BU10: 19932206
A11: Austria | B11: =VLOOKUP(A11,'storage capacity'!$A$2:$C$195,3,FALSE) -> Other eurasia | C11: 671762.73 | D11: 699333.44 | E11: 727748.69 | F11: 757022.81 | G11: 787169.99 | H11: 818204.24 | I11: 850139.45 | J11: 882989.3 | K11: 916767.29 | L11: 951486.72 | M11: 987160.7 | N11: 1023802.1 | O11: 1061423.5 | P11: 1100037.3 | Q11: 1139655.8 | R11: 1180290.6 | S11: 1221953.4 | T11: 1264655.6 | U11: 1308408 | V11: 1353221.5 | W11: 1399106.4 | X11: 1446072.7 | Y11: 1494130.3 | Z11: 1543288.3 | AA11: 1593556 | AB11: 1644941.9 | AC11: 1697454.3 | AD11: 1751101.3 | AE11: 1805890.3 | AF11: 1861828.6 | AG11: 1918922.8 | AH11: 1977179.5 | AI11: 2036604.5 | AJ11: 2097203.4 | AK11: 2158981.4 | AL11: 2221943.3 | AM11: 2286093.3 | AN11: 2351435.4 | AO11: 2417973 | AP11: 2485709.2 | AQ11: 2554646.6 | AR11: 2624787.4 | AS11: 2696133.3 | AT11: 2768685.7 | AU11: 2842445.4 | AV11: 2917412.8 | AW11: 2993588 | AX11: 3070970.6 | AY11: 3149559.6 | AZ11: 3229353.7 | BA11: 3310351.3 | BB11: 3392550.2 | BC11: 3475947.8 | BD11: 3560540.9 | BE11: 3646326.3 | BF11: 3733300.1 | BG11: 3821457.8 | BH11: 3910795 | BI11: 4001306.3 | BJ11: 4092986.4 | BK11: 4185829.4 | BL11: 4279828.8 | BM11: 4374978 | BN11: 4471270 | BO11: 4568697.2 | BP11: 4667251.7 | BQ11: 4766925.5 | BR11: 4867709.9 | BS11: 4969596 | BT11: 5072574.4 | BU11: 5176635.6
A12: Azerbaijan | B12: =VLOOKUP(A12,'storage capacity'!$A$2:$C$195,3,FALSE) -> Other eurasia | C12: 99479.6 | D12: 103023.26 | E12: 106656.46 | F12: 110380.17 | G12: 114195.34 | H12: 118102.92 | I12: 122103.79 | J12: 126198.84 | K12: 130388.89 | L12: 134674.77 | M12: 139057.27 | N12: 143537.12 | O12: 148115.06 | P12: 152791.76 | Q12: 157567.88 | R12: 162444.05 | S12: 167420.85 | T12: 172498.83 | U12: 177678.5 | V12: 182960.36 | W12: 188344.84 | X12: 193832.36 | Y12: 199423.28 | Z12: 205117.95 | AA12: 210916.65 | AB12: 216819.67 | AC12: 222827.21 | AD12: 228939.46 | AE12: 235156.58 | AF12: 241478.67 | AG12: 247905.81 | AH12: 254438.03 | AI12: 261075.33 | AJ12: 267817.66 | AK12: 274664.95 | AL12: 281617.08 | AM12: 288673.9 | AN12: 295835.22 | AO12: 303100.8 | AP12: 310470.38 | AQ12: 317943.65 | AR12: 325520.28 | AS12: 333199.89 | AT12: 340982.07 | AU12: 348866.37 | AV12: 356852.31 | AW12: 364939.36 | AX12: 373126.99 | AY12: 381414.59 | AZ12: 389801.56 | BA12: 398287.23 | BB12: 406870.92 | BC12: 415551.92 | BD12: 424329.48 | BE12: 433202.81 | BF12: 442171.11 | BG12: 451233.53 | BH12: 460389.21 | BI12: 469637.24 | BJ12: 478976.7 | BK12: 488406.65 | BL12: 497926.09 | BM12: 507534.02 | BN12: 517229.41 | BO12: 527011.21 | BP12: 536878.33 | BQ12: 546829.68 | BR12: 556864.12 | BS12: 566980.5 | BT12: 577177.67 | BU12: 587454.43
A13: Bahamas | B13: =VLOOKUP(A13,'storage capacity'!$A$2:$C$195,3,FALSE) -> Other latin america | C13: 18922.867 | D13: 19774.024 | E13: 20654.572 | F13: 21565.133 | G13: 22506.33 | H13: 23478.782 | I13: 24483.107 | J13: 25519.92 | K13: 26589.833 | L13: 27693.454 | M13: 28831.387 | N13: 30004.23 | O13: 31212.579 | P13: 32457.022 | Q13: 33738.139 | R13: 35056.507 | S13: 36412.693 | T13: 37807.258 | U13: 39240.753 | V13: 40713.722 | W13: 42226.698 | X13: 43780.207 | Y13: 45374.763 | Z13: 47010.869 | AA13: 48689.018 | AB13: 50409.691 | AC13: 52173.358 | AD13: 53980.476 | AE13: 55831.49 | AF13: 57726.832 | AG13: 59666.918 | AH13: 61652.154 | AI13: 63682.93 | AJ13: 65759.622 | AK13: 67882.59 | AL13: 70052.181 | AM13: 72268.724 | AN13: 74532.535 | AO13: 76843.912 | AP13: 79203.138 | AQ13: 81610.48 | AR13: 84066.186 | AS13: 86570.49 | AT13: 89123.608 | AU13: 91725.737 | AV13: 94377.059 | AW13: 97077.738 | AX13: 99827.919 | AY13: 102627.73 | AZ13: 105477.29 | BA13: 108376.67 | BB13: 111325.97 | BC13: 114325.23 | BD13: 117374.49 | BE13: 120473.78 | BF13: 123623.09 | BG13: 126822.41 | BH13: 130071.71 | BI13: 133370.94 | BJ13: 136720.01 | BK13: 140118.86 | BL13: 143567.36 | BM13: 147065.41 | BN13: 150612.85 | BO13: 154209.53 | BP13: 157855.28 | BQ13: 161549.9 | BR13: 165293.18 | BS13: 169084.89 | BT13: 172924.8 | BU13: 176812.64
... A43: Croatia | B43: =VLOOKUP(A43,'storage capacity'!$A$2:$C$195,3,FALSE) -> Other eurasia | C43: 125658.33 | D43: 133132.04 | E43: 140971.07 | F43: 149188.67 | G43: 157798.33 | H43: 166813.78 | I43: 176249.01 | J43: 186118.22 | K43: 196435.85 | L43: 207216.55 | M43: 218475.18 | N43: 230226.83 | O43: 242486.75 | P43: 255270.4 | Q43: 268593.41 | R43: 282471.6 | S43: 296920.91 | T43: 311957.47 | U43: 327597.53 | V43: 343857.46 | W43: 360753.76 | X43: 378303.04 | Y43: 396522 | Z43: 415427.41 | AA43: 435036.12 | AB43: 455365.06 | AC43: 476431.15 | AD43: 498251.41 | AE43: 520842.82 | AF43: 544222.4 | AG43: 568407.15 | AH43: 593414.05 | AI43: 619260.06 | AJ43: 645962.06 | AK43: 673536.9 | AL43: 702001.34 | AM43: 731372.04 | AN43: 761665.57 | AO43: 792898.38 | AP43: 825086.79 | AQ43: 858246.96 | AR43: 892394.91 | AS43: 927546.47 | AT43: 963717.3 | AU43: 1000922.8 | AV43: 1039178.3 | AW43: 1078498.8 | AX43: 1118898.9 | AY43: 1160393.3 | AZ43: 1202996.2 | BA43: 1246721.6 | BB43: 1291583.1 | BC43: 1337594.1 | BD43: 1384767.7 | BE43: 1433116.6 | BF43: 1482653.3 | BG43: 1533389.7 | BH43: 1585337.6 | BI43: 1638508.3 | BJ43: 1692912.8 | BK43: 1748561.6 | BL43: 1805464.8 | BM43: 1863632.3 | BN43: 1923073.4 | BO43: 1983797 | BP43: 2045811.7 | BQ43: 2109125.4 | BR43: 2173745.8 | BS43: 2239680.1 | BT43: 2306935 | BU43: 2375516.7
A44: Cuba | B44: =VLOOKUP(A44,'storage capacity'!$A$2:$C$195,3,FALSE) -> Other latin america
A45: Cyprus | B45: =VLOOKUP(A45,'storage capacity'!$A$2:$C$195,3,FALSE) -> Other eurasia | C45: 48760.333 | D45: 51536.714 | E45: 54441.835 | F45: 57480.029 | G45: 60655.696 | H45: 63973.301 | I45: 67437.375 | J45: 71052.507 | K45: 74823.347 | L45: 78754.601 | M45: 82851.026 | N45: 87117.432 | O45: 91558.675 | P45: 96179.656 | Q45: 100985.32 | R45: 105980.64 | S45: 111170.63 | T45: 116560.34 | U45: 122154.84 | V45: 127959.23 | W45: 133978.63 | X45: 140218.16 | Y45: 146682.96 | Z45: 153378.21 | AA45: 160309.04 | AB45: 167480.62 | AC45: 174898.11 | AD45: 182566.65 | AE45: 190491.37 | AF45: 198677.4 | AG45: 207129.82 | AH45: 215853.73 | AI45: 224854.15 | AJ45: 234136.11 | AK45: 243704.57 | AL45: 253564.47 | AM45: 263720.7 | AN45: 274178.1 | AO45: 284941.44 | AP45: 296015.47 | AQ45: 307404.83 | AR45: 319114.12 | AS45: 331147.88 | AT45: 343510.56 | AU45: 356206.53 | AV45: 369240.08 | AW45: 382615.43 | AX45: 396336.68 | AY45: 410407.87 | AZ45: 424832.92 | BA45: 439615.66 | BB45: 454759.82 | BC45: 470269.02 | BD45: 486146.77 | BE45: 502396.46 | BF45: 519021.37 | BG45: 536024.68 | BH45: 553409.41 | BI45: 571178.49 | BJ45: 589334.71 | BK45: 607880.74 | BL45: 626819.1 | BM45: 646152.2 | BN45: 665882.3 | BO45: 686011.52 | BP45: 706541.87 | BQ45: 727475.18 | BR45: 748813.16 | BS45: 770557.38 | BT45: 792709.26 | BU45: 815270.07
A46: Czech Republic | B46: =VLOOKUP(A46,'storage capacity'!$A$2:$C$195,3,FALSE) -> Other eurasia | C46: 447733.13 | D46: 472713.24 | E46: 498823.31 | F46: 526100.04 | G46: 554580.63 | H46: 584302.8 | I46: 615304.76 | J46: 647625.14 | K46: 681303.05 | L46: 716378 | M46: 752889.87 | N46: 790878.92 | O46: 830385.76 | P46: 871451.28 | Q46: 914116.67 | R46: 958423.37 | S46: 1004413.1 | T46: 1052127.6 | U46: 1101609 | V46: 1152899.3 | W46: 1206041 | X46: 1261076.3 | Y46: 1318047.5 | Z46: 1376997 | AA46: 1437967.2 | AB46: 1501000.4 | AC46: 1566138.6 | AD46: 1633423.9 | AE46: 1702898.2 | AF46: 1774603.1 | AG46: 1848580.2 | AH46: 1924870.5 | AI46: 2003514.8 | AJ46: 2084553.8 | AK46: 2168027.5 | AL46: 2253975.6 | AM46: 2342437.5 | AN46: 2433451.9 | AO46: 2527057.1 | AP46: 2623290.9 | AQ46: 2722190.4 | AR46: 2823792.2 | AS46: 2928132.2 | AT46: 3035245.7 | AU46: 3145167.1 | AV46: 3257930.3 | AW46: 3373568.3 | AX46: 3492113.4 | AY46: 3613596.9 | AZ46: 3738049.6 | BA46: 3865501 | BB46: 3995980 | BC46: 4129514.5 | BD46: 4266131.3 | BE46: 4405856.5 | BF46: 4548714.9 | BG46: 4694730.6 | BH46: 4843926.4 | BI46: 4996324.2 | BJ46: 5151944.8 | BK46: 5310807.8 | BL46: 5472931.8 | BM46: 5638334.3 | BN46: 5807031.5 | BO46: 5979038.7 | BP46: 6154369.8 | BQ46: 6333037.6 | BR46: 6515053.8 | BS46: 6700428.8 | BT46: 6889171.8 | BU46: 7081290.9
A47: Denmark | B47: =VLOOKUP(A47,'storage capacity'!$A$2:$C$195,3,FALSE) -> Country specific | C47: 509516.67 | D47: 530191.67 | E47: 551490.47 | F47: 573423.34 | G47: 596000.43 | H47: 619231.78 | I47: 643127.29 | J47: 667696.73 | K47: 692949.71 | L47: 718895.71 | M47: 745544.02 | N47: 772903.79 | O47: 800983.95 | P47: 829793.29 | Q47: 859340.37 | R47: 889633.56 | S47: 920681.03 | T47: 952490.71 | U47: 985070.34 | V47: 1018427.4 | W47: 1052569.2 | X47: 1087502.6 | Y47: 1123234.6 | Z47: 1159771.5 | AA47: 1197119.6 | AB47: 1235285 | AC47: 1274273.3 | AD47: 1314089.9 | AE47: 1354740.1 | AF47: 1396228.7 | AG47: 1438560.2 | AH47: 1481739.1 | AI47: 1525769.2 | AJ47: 1570654.3 | AK47: 1616397.7 | AL47: 1663002.7 | AM47: 1710471.9 | AN47: 1758807.8 | AO47: 1808012.6 | AP47: 1858088.2 | AQ47: 1909036.1 | AR47: 1960857.4 | AS47: 2013553.3 | AT47: 2067124.1 | AU47: 2121570.2 | AV47: 2176891.6 | AW47: 2233087.9 | AX47: 2290158.4 | AY47: 2348102.2 | AZ47: 2406917.9 | BA47: 2466604 | BB47: 2527158.4 | BC47: 2588579.1 | BD47: 2650863.4 | BE47: 2714008.5 | BF47: 2778011.3 | BG47: 2842868.3 | BH47: 2908575.8 | BI47: 2975129.7 | BJ47: 3042525.7 | BK47: 3110759.2 | BL47: 3179825.4 | BM47: 3249718.9 | BN47: 3320434.5 | BO47: 3391966.3 | BP47: 3464308.4 | BQ47: 3537454.5 | BR47: 3611398.2 | BS47: 3686132.5 | BT47: 3761650.7 | BU47: 3837945.3
A48: Djibouti | B48: =VLOOKUP(A48,'storage capacity'!$A$2:$C$195,3,FALSE) -> Sub-saharan africa | C48: 6471.8667 | D48: 6695.4755 | E48: 6924.4969 | F48: 7158.9835 | G48: 7398.9863 | H48: 7644.5547 | I48: 7895.7361 | J48: 8152.5764 | K48: 8415.1196 | L48: 8683.4076 | M48: 8957.4806 | N48: 9237.377 | O48: 9523.1329 | P48: 9814.7826 | Q48: 10112.358 | R48: 10415.89 | S48: 10725.407 | T48: 11040.934 | U48: 11362.495 | V48: 11690.112 | W48: 12023.805 | X48: 12363.591 | Y48: 12709.485 | Z48: 13061.5 | AA48: 13419.648 | AB48: 13783.936 | AC48: 14154.371 | AD48: 14530.958 | AE48: 14913.698 | AF48: 15302.591 | AG48: 15697.635 | AH48: 16098.824 | AI48: 16506.152 | AJ48: 16919.611 | AK48: 17339.187 | AL48: 17764.869 | AM48: 18196.639 | AN48: 18634.481 | AO48: 19078.375 | AP48: 19528.298 | AQ48: 19984.226 | AR48: 20446.133 | AS48: 20913.991 | AT48: 21387.768 | AU48: 21867.433 | AV48: 22352.952 | AW48: 22844.287 | AX48: 23341.401 | AY48: 23844.254 | AZ48: 24352.802 | BA48: 24867.003 | BB48: 25386.811 | BC48: 25912.177 | BD48: 26443.054 | BE48: 26979.389 | BF48: 27521.131 | BG48: 28068.224 | BH48: 28620.613 | BI48: 29178.241 | BJ48: 29741.048 | BK48: 30308.975 | BL48: 30881.959 | BM48: 31459.936 | BN48: 32042.843 | BO48: 32630.614 | BP48: 33223.18 | BQ48: 33820.474 | BR48: 34422.427 | BS48: 35028.966 | BT48: 35640.02 | BU48: 36255.517
A49: Dominica | B49: =VLOOKUP(A49,'storage capacity'!$A$2:$C$195,3,FALSE) -> Sub-saharan africa | C49: 960.46667 | D49: 1033.1977 | E49: 1110.6538 | F49: 1193.084 | G49: 1280.7465 | H49: 1373.909 | I49: 1472.8488 | J49: 1577.853 | K49: 1689.2183 | L49: 1807.2516 | M49: 1932.2696 | N49: 2064.5992 | O49: 2204.5773 | P49: 2352.5511 | Q49: 2508.878 | R49: 2673.9257 | S49: 2848.0721 | T49: 3031.7054 | U49: 3225.2239 | V49: 3429.0362 | W49: 3643.5613 | X49: 3869.2278 | Y49: 4106.4748 | Z49: 4355.7509 | AA49: 4617.5147 | AB49: 4892.2347 | AC49: 5180.3885 | AD49: 5482.4633 | AE49: 5798.9556 | AF49: 6130.3709 | AG49: 6477.2232 | AH49: 6840.0354 | AI49: 7219.3387 | AJ49: 7615.6722 | AK49: 8029.5831 | AL49: 8461.626 | AM49: 8912.3626 | AN49: 9382.3617 | AO49: 9872.1987 | AP49: 10382.455 | AQ49: 10913.718 | AR49: 11466.582 | AS49: 12041.643 | AT49: 12639.505 | AU49: 13260.776 | AV49: 13906.065 | AW49: 14575.989 | AX49: 15271.164 | AY49: 15992.211 | AZ49: 16739.752 | BA49: 17514.411 | BB49: 18316.814 | BC49: 19147.586 | BD49: 20007.355 | BE49: 20896.745 | BF49: 21816.381 | BG49: 22766.889 | BH49: 23748.89 | BI49: 24763.003 | BJ49: 25809.847 | BK49: 26890.034 | BL49: 28004.175 | BM49: 29152.876 | BN49: 30336.737 | BO49: 31556.354 | BP49: 32812.316 | BQ49: 34105.206 | BR49: 35435.601 | BS49: 36804.071 | BT49: 38211.175 | BU49: 39657.467
A50: Dominican Republic | B50: =VLOOKUP(A50,'storage capacity'!$A$2:$C$195,3,FALSE) -> Sub-saharan africa | C50: 188471.47 | D50: 200415.14 | E50: 212988.7 | F50: 226217.46 | G50: 240127.37 | H50: 254744.92 | I50: 270097.24 | J50: 286211.99 | K50: 303117.44 | L50: 320842.38 | M50: 339416.19 | N50: 358868.75 | O50: 379230.5 | P50: 400532.39 | Q50: 422805.84 | R50: 446082.79 | S50: 470395.64 | T50: 495777.22 | U50: 522260.84 | V50: 549880.18 | W50: 578669.35 | X50: 608662.82 | Y50: 639895.43 | Z50: 672402.34 | AA50: 706219.03 | AB50: 741381.26 | AC50: 777925.08 | AD50: 815886.74 | AE50: 855302.73 | AF50: 896209.74 | AG50: 938644.59 | AH50: 982644.26 | AI50: 1028245.8 | AJ50: 1075486.4 | AK50: 1124403.3 | AL50: 1175033.7 | AM50: 1227414.8 | AN50: 1281583.8 | AO50: 1337577.8 | AP50: 1395433.8 | AQ50: 1455188.8 | AR50: 1516879.5 | AS50: 1580542.4 | AT50: 1646213.9 | AU50: 1713930 | AV50: 1783726.6 | AW50: 1855639.1 | AX50: 1929702.7 | AY50: 2005952.1 | AZ50: 2084421.9 | BA50: 2165145.9 | BB50: 2248157.6 | BC50: 2333490 | BD50: 2421175.6 | BE50: 2511246.4 | BF50: 2603733.7 | BG50: 2698668.4 | BH50: 2796080.4 | BI50: 2895999.5 | BJ50: 2998454.2 | BK50: 3103472.8 | BL50: 3211082.7 | BM50: 3321310.4 | BN50: 3434181.8 | BO50: 3549721.9 | BP50: 3667955.1 | BQ50: 3788904.5 | BR50: 3912592.9 | BS50: 4039041.8 | BT50: 4168272 | BU50: 4300303.3
A51: DR Congo | B51: =VLOOKUP(A51,'storage capacity'!$A$2:$C$195,3,FALSE) -> Sub-saharan africa | C51: 106252.13 | D51: 113827.43 | E51: 121861.66 | F51: 130376.94 | G51: 139396.15 | H51: 148942.86 | I51: 159041.37 | J51: 169716.75 | K51: 180994.77 | L51: 192901.97 | M51: 205465.61 | N51: 218713.69 | O51: 232674.96 | P51: 247378.91 | Q51: 262855.74 | R51: 279136.41 | S51: 296252.57 | T51: 314236.6 | U51: 333121.6 | V51: 352941.36 | W51: 373730.34 | X51: 395523.7 | Y51: 418357.25 | Z51: 442267.47 | AA51: 467291.45 | AB51: 493466.92 | AC51: 520832.19 | AD51: 549426.19 | AE51: 579288.37 | AF51: 610458.75 | AG51: 642977.88 | AH51: 676886.79 | AI51: 712226.99 | AJ51: 749040.45 | AK51: 787369.55 | AL51: 827257.08 | AM51: 868746.2 | AN51: 911880.41 | AO51: 956703.53 | AP51: 1003259.6 | AQ51: 1051593.1 | AR51: 1101748.5 | AS51: 1153770.5 | AT51: 1207704.1 | AU51: 1263594.3 | AV51: 1321486.3 | AW51: 1381425.1 | AX51: 1443456.1 | AY51: 1507624.2 | AZ51: 1573974.8 | BA51: 1642552.7 | BB51: 1713402.8 | BC51: 1786570 | BD51: 1862098.7 | BE51: 1940033.3 | BF51: 2020417.7 | BG51: 2103295.6 | BH51: 2188710.4 | BI51: 2276705 | BJ51: 2367322.1 | BK51: 2460603.6 | BL51: 2556591.3 | BM51: 2655326 | BN51: 2756848.4 | BO51: 2861198.4 | BP51: 2968415 | BQ51: 3078537.1 | BR51: 3191602.3 | BS51: 3307647.9 | BT51: 3426710.3 | BU51: 3548824.9
A52: Ecuador | B52: =VLOOKUP(A52,'storage capacity'!$A$2:$C$195,3,FALSE) -> Other latin america | C52: 150617 | D52: 156510.97 | E52: 162574.34 | F52: 168809.63 | G52: 175219.32 | H52: 181805.85 | I52: 188571.63 | J52: 195519.02 | K52: 202650.33 | L52: 209967.84 | M52: 217473.75 | N52: 225170.25 | O52: 233059.43 | P52: 241143.37 | Q52: 249424.07 | R52: 257903.47 | S52: 266583.46 | T52: 275465.86 | U52: 284552.44 | V52: 293844.88 | W52: 303344.82 | X52: 313053.82 | Y52: 322973.38 | Z52: 333104.91 | AA52: 343449.77 | AB52: 354009.24 | AC52: 364784.52 | AD52: 375776.74 | AE52: 386986.96 | AF52: 398416.17 | AG52: 410065.25 | AH52: 421935.03 | AI52: 434026.27 | AJ52: 446339.62 | AK52: 458875.68 | AL52: 471634.95 | AM52: 484617.85 | AN52: 497824.74 | AO52: 511255.88 | AP52: 524911.45 | AQ52: 538791.55 | AR52: 552896.21 | AS52: 567225.37 | AT52: 581778.89 | AU52: 596556.54 | AV52: 611558.03 | AW52: 626782.96 | AX52: 642230.89 | AY52: 657901.27 | AZ52: 673793.47 | BA52: 689906.81 | BB52: 706240.5 | BC52: 722793.68 | BD52: 739565.44 | BE52: 756554.76 | BF52: 773760.56 | BG52: 791181.7 | BH52: 808816.93 | BI52: 826664.97 | BJ52: 844724.43 | BK52: 862993.89 | BL52: 881471.83 | BM52: 900156.67 | BN52: 919046.77 | BO52: 938140.42 | BP52: 957435.85 | BQ52: 976931.21 | BR52: 996624.62 | BS52: 1016514.1 | BT52: 1036597.7 | BU52: 1056873.2
A53: Egypt | B53: =VLOOKUP(A53,'storage capacity'!$A$2:$C$195,3,FALSE) -> Country specific | C53: 472622.8 | D53: 496797.45 | E53: 521954.53 | F53: 548121.21 | G53: 575324.9 | H53: 603593.19 | I53: 632953.85 | J53: 663434.83 | K53: 695064.17 | L53: 727870.08 | M53: 761880.83 | N53: 797124.78 | O53: 833630.34 | P53: 871425.96 | Q53: 910540.08 | R53: 951001.15 | S53: 992837.58 | T53: 1036077.7 | U53: 1080749.8 | V53: 1126882 | W53: 1174502.4 | X53: 1223638.8 | Y53: 1274318.9 | Z53: 1326570.3 | AA53: 1380420.3 | AB53: 1435895.8 | AC53: 1493023.7 | AD53: 1551830.5 | AE53: 1612342.3 | AF53: 1674585 | AG53: 1738584 | AH53: 1804364.5 | AI53: 1871951.2 | AJ53: 1941368.3 | AK53: 2012639.6 | AL53: 2085788.6 | AM53: 2160838.1 | AN53: 2237810.4 | AO53: 2316727.5 | AP53: 2397610.6 | AQ53: 2480480.5 | AR53: 2565357.4 | AS53: 2652260.7 | AT53: 2741209.5 | AU53: 2832222 | AV53: 2925316 | AW53: 3020508.3 | AX53: 3117815.5 | AY53: 3217252.9 | AZ53: 3318835.7 | BA53: 3422578 | BB53: 3528493.3 | BC53: 3636594.4 | BD53: 3746893.1 | BE53: 3859400.8 | BF53: 3974127.9 | BG53: 4091084.1 | BH53: 4210278.2 | BI53: 4331718.4 | BJ53: 4455411.9 | BK53: 4581365.4 | BL53: 4709584.3 | BM53: 4840073.6 | BN53: 4972837.4 | BO53: 5107878.9 | BP53: 5245200.4 | BQ53: 5384803.6 | BR53: 5526689.2 | BS53: 5670857.1 | BT53: 5817306.5 | BU53: 5966035.6
A54: El Salvador | B54: =VLOOKUP(A54,'storage capacity'!$A$2:$C$195,3,FALSE) -> Other latin america | C54: 48054.467 | D54: 50616.656 | E54: 53288.469 | F54: 56073.186 | G54: 58974.122 | H54: 61994.628 | I54: 65138.085 | J54: 68407.903 | K54: 71807.52 | L54: 75340.4 | M54: 79010.029 | N54: 82819.911 | O54: 86773.571 | P54: 90874.547 | Q54: 95126.39 | R54: 99532.661 | S54: 104096.93 | T54: 108822.76 | U54: 113713.74 | V54: 118773.43 | W54: 124005.4 | X54: 129413.21 | Y54: 135000.42 | Z54: 140770.57 | AA54: 146727.18 | AB54: 152873.74 | AC54: 159213.76 | AD54: 165750.68 | AE54: 172487.93 | AF54: 179428.92 | AG54: 186577.02 | AH54: 193935.56 | AI54: 201507.82 | AJ54: 209297.07 | AK54: 217306.51 | AL54: 225539.29 | AM54: 233998.54 | AN54: 242687.29 | AO54: 251608.56 | AP54: 260765.29 | AQ54: 270160.35 | AR54: 279796.57 | AS54: 289676.71 | AT54: 299803.44 | AU54: 310179.38 | AV54: 320807.07 | AW54: 331688.98 | AX54: 342827.49 | AY54: 354224.93 | AZ54: 365883.52 | BA54: 377805.4 | BB54: 389992.64 | BC54: 402447.21 | BD54: 415171 | BE54: 428165.8 | BF54: 441433.32 | BG54: 454975.18 | BH54: 468792.89 | BI54: 482887.87 | BJ54: 497261.45 | BK54: 511914.86 | BL54: 526849.23 | BM54: 542065.59 | BN54: 557564.86 | BO54: 573347.88 | BP54: 589415.37 | BQ54: 605767.96 | BR54: 622406.17 | BS54: 639330.42 | BT54: 656541.02 | BU54: 674038.18
A55: Equatorial Guinea | B55: =VLOOKUP(A55,'storage capacity'!$A$2:$C$195,3,FALSE) -> Sub-saharan africa | C55: 14642.667 | D55: 15167.844 | E55: 15706.417 | F55: 16258.537 | G55: 16824.35 | H55: 17403.999 | I55: 17997.622 | J55: 18605.354 | K55: 19227.324 | L55: 19863.66 | M55: 20514.481 | N55: 21179.905 | O55: 21860.043 | P55: 22555.002 | Q55: 23264.884 | R55: 23989.786 | S55: 24729.8 | T55: 25485.013 | U55: 26255.506 | V55: 27041.357 | W55: 27842.634 | X55: 28659.404 | Y55: 29491.728 | Z55: 30339.658 | AA55: 31203.245 | AB55: 32082.531 | AC55: 32977.554 | AD55: 33888.346 | AE55: 34814.934 | AF55: 35757.337 | AG55: 36715.571 | AH55: 37689.645 | AI55: 38679.562 | AJ55: 39685.32 | AK55: 40706.911 | AL55: 41744.321 | AM55: 42797.531 | AN55: 43866.516 | AO55: 44951.245 | AP55: 46051.681 | AQ55: 47167.783 | AR55: 48299.503 | AS55: 49446.788 | AT55: 50609.58 | AU55: 51787.815 | AV55: 52981.423 | AW55: 54190.331 | AX55: 55414.458 | AY55: 56653.72 | AZ55: 57908.026 | BA55: 59177.281 | BB55: 60461.386 | BC55: 61760.236 | BD55: 63073.72 | BE55: 64401.724 | BF55: 65744.13 | BG55: 67100.813 | BH55: 68471.646 | BI55: 69856.495 | BJ55: 71255.225 | BK55: 72667.694 | BL55: 74093.758 | BM55: 75533.266 | BN55: 76986.067 | BO55: 78452.004 | BP55: 79930.916 | BQ55: 81422.639 | BR55: 82927.006 | BS55: 84443.846 | BT55: 85972.985 | BU55: 87514.246
A56: Eritrea | B56: =VLOOKUP(A56,'storage capacity'!$A$2:$C$195,3,FALSE) -> Sub-saharan africa | C56: 1982 | D56: 1982 | E56: 1982 | F56: 1982 | G56: 1982 | H56: 1982 | I56: 1982 | J56: 1982 | K56: 1982 | L56: 1982 | M56: 1982 | N56: 1982 | O56: 1982 | P56: 1982 | Q56: 1982 | R56: 1982 | S56: 1982 | T56: 1982 | U56: 1982 | V56: 1982 | W56: 1982 | X56: 1982 | Y56: 1982 | Z56: 1982 | AA56: 1982 | AB56: 1982 | AC56: 1982 | AD56: 1982 | AE56: 1982 | AF56: 1982 | AG56: 1982 | AH56: 1982 | AI56: 1982 | AJ56: 1982 | AK56: 1982 | AL56: 1982 | AM56: 1982 | AN56: 1982 | AO56: 1982 | AP56: 1982 | AQ56: 1982 | AR56: 1982 | AS56: 1982 | AT56: 1982 | AU56: 1982 | AV56: 1982 | AW56: 1982 | AX56: 1982 | AY56: 1982 | AZ56: 1982 | BA56: 1982 | BB56: 1982 | BC56: 1982 | BD56: 1982 | BE56: 1982 | BF56: 1982 | BG56: 1982 | BH56: 1982 | BI56: 1982 | BJ56: 1982 | BK56: 1982 | BL56: 1982 | BM56: 1982 | BN56: 1982 | BO56: 1982 | BP56: 1982 | BQ56: 1982 | BR56: 1982 | BS56: 1982 | BT56: 1982 | BU56: 1982
... A74: Haiti | B74: =VLOOKUP(A74,'storage capacity'!$A$2:$C$195,3,FALSE) -> Other latin america | C74: 41370.533 | D74: 43407.205 | E74: 45522.772 | F74: 47719.261 | G74: 49998.706 | H74: 52363.152 | I74: 54814.651 | J74: 57355.259 | K74: 59987.038 | L74: 62712.053 | M74: 65532.368 | N74: 68450.049 | O74: 71467.156 | P74: 74585.749 | Q74: 77807.88 | R74: 81135.596 | S74: 84570.932 | T74: 88115.915 | U74: 91772.557 | V74: 95542.86 | W74: 99428.806 | X74: 103432.36 | Y74: 107555.48 | Z74: 111800.08 | AA74: 116168.07 | AB74: 120661.32 | AC74: 125281.7 | AD74: 130031.04 | AE74: 134911.12 | AF74: 139923.72 | AG74: 145070.57 | AH74: 150353.38 | AI74: 155773.82 | AJ74: 161333.51 | AK74: 167034.05 | AL74: 172876.99 | AM74: 178863.84 | AN74: 184996.09 | AO74: 191275.15 | AP74: 197702.41 | AQ74: 204279.2 | AR74: 211006.83 | AS74: 217886.53 | AT74: 224919.49 | AU74: 232106.87 | AV74: 239449.75 | AW74: 246949.17 | AX74: 254606.13 | AY74: 262421.56 | AZ74: 270396.34 | BA74: 278531.3 | BB74: 286827.2 | BC74: 295284.76 | BD74: 303904.64 | BE74: 312687.43 | BF74: 321633.68 | BG74: 330743.86 | BH74: 340018.4 | BI74: 349457.67 | BJ74: 359061.97 | BK74: 368831.55 | BL74: 378766.59 | BM74: 388867.22 | BN74: 399133.5 | BO74: 409565.45 | BP74: 420163 | BQ74: 430926.05 | BR74: 441854.42 | BS74: 452947.88 | BT74: 464206.15 | BU74: 475628.86
A75: Holy See | B75: =VLOOKUP(A75,'storage capacity'!$A$2:$C$195,3,FALSE) -> #N/A
A76: Honduras | B76: =VLOOKUP(A76,'storage capacity'!$A$2:$C$195,3,FALSE) -> Other latin america | C76: 51868 | D76: 54172.737 | E76: 56555.813 | F76: 59018.843 | G76: 61563.435 | H76: 64191.194 | I76: 66903.717 | J76: 69702.59 | K76: 72589.394 | L76: 75565.694 | M76: 78633.044 | N76: 81792.985 | O76: 85047.041 | P76: 88396.723 | Q76: 91843.519 | R76: 95388.902 | S76: 99034.323 | T76: 102781.21 | U76: 106630.97 | V76: 110584.99 | W76: 114644.63 | X76: 118811.21 | Y76: 123086.03 | Z76: 127470.38 | AA76: 131965.49 | AB76: 136572.59 | AC76: 141292.84 | AD76: 146127.4 | AE76: 151077.39 | AF76: 156143.87 | AG76: 161327.9 | AH76: 166630.48 | AI76: 172052.58 | AJ76: 177595.13 | AK76: 183259.01 | AL76: 189045.08 | AM76: 194954.15 | AN76: 200986.99 | AO76: 207144.31 | AP76: 213426.81 | AQ76: 219835.12 | AR76: 226369.84 | AS76: 233031.51 | AT76: 239820.65 | AU76: 246737.72 | AV76: 253783.13 | AW76: 260957.24 | AX76: 268260.39 | AY76: 275692.85 | AZ76: 283254.86 | BA76: 290946.58 | BB76: 298768.17 | BC76: 306719.71 | BD76: 314801.24 | BE76: 323012.76 | BF76: 331354.22 | BG76: 339825.53 | BH76: 348426.52 | BI76: 357157.03 | BJ76: 366016.79 | BK76: 375005.55 | BL76: 384122.95 | BM76: 393368.64 | BN76: 402742.18 | BO76: 412243.11 | BP76: 421870.93 | BQ76: 431625.07 | BR76: 441504.95 | BS76: 451509.91 | BT76: 461639.28 | BU76: 471892.33
A77: Hungary | B77: =VLOOKUP(A77,'storage capacity'!$A$2:$C$195,3,FALSE) -> Other eurasia | C77: 327522.87 | D77: 347455.43 | E77: 368389.59 | F77: 390363.09 | G77: 413414.41 | H77: 437582.8 | I77: 462908.28 | J77: 489431.58 | K77: 517194.15 | L77: 546238.17 | M77: 576606.45 | N77: 608342.5 | O77: 641490.45 | P77: 676095.06 | Q77: 712201.67 | R77: 749856.19 | S77: 789105.07 | T77: 829995.29 | U77: 872574.28 | V77: 916889.95 | W77: 962990.63 | X77: 1010925 | Y77: 1060742.3 | Z77: 1112491.7 | AA77: 1166223 | AB77: 1221986.2 | AC77: 1279831.5 | AD77: 1339809.1 | AE77: 1401969.6 | AF77: 1466363.6 | AG77: 1533041.8 | AH77: 1602054.8 | AI77: 1673453.5 | AJ77: 1747288.3 | AK77: 1823609.9 | AL77: 1902468.7 | AM77: 1983914.8 | AN77: 2067998.5 | AO77: 2154769.3 | AP77: 2244276.8 | AQ77: 2336570.2 | AR77: 2431698.1 | AS77: 2529709 | AT77: 2630650.6 | AU77: 2734570.3 | AV77: 2841514.9 | AW77: 2951530.7 | AX77: 3064663.3 | AY77: 3180957.6 | AZ77: 3300457.8 | BA77: 3423207.4 | BB77: 3549249.1 | BC77: 3678624.9 | BD77: 3811375.6 | BE77: 3947541.6 | BF77: 4087161.9 | BG77: 4230274.9 | BH77: 4376917.7 | BI77: 4527126.7 | BJ77: 4680937 | BK77: 4838382.6 | BL77: 4999496.6 | BM77: 5164310.8 | BN77: 5332855.8 | BO77: 5505161.1 | BP77: 5681254.8 | BQ77: 5861164 | BR77: 6044914.3 | BS77: 6232530.2 | BT77: 6424034.7 | BU77: 6619449.7
A78: Iceland | B78: =VLOOKUP(A78,'storage capacity'!$A$2:$C$195,3,FALSE) -> Country specific | C78: 49642.067 | D78: 53481.234 | E78: 57575.949 | F78: 61940.089 | G78: 66588.073 | H78: 71534.873 | I78: 76796.026 | J78: 82387.638 | K78: 88326.395 | L78: 94629.568 | M78: 101315.02 | N78: 108401.21 | O78: 115907.21 | P78: 123852.69 | Q78: 132257.93 | R78: 141143.83 | S78: 150531.91 | T78: 160444.31 | U78: 170903.79 | V78: 181933.71 | W78: 193558.07 | X78: 205801.47 | Y78: 218689.15 | Z78: 232246.94 | AA78: 246501.26 | AB78: 261479.16 | AC78: 277208.27 | AD78: 293716.8 | AE78: 311033.54 | AF78: 329187.85 | AG78: 348209.65 | AH78: 368129.4 | AI78: 388978.08 | AJ78: 410787.22 | AK78: 433588.83 | AL78: 457415.42 | AM78: 482299.97 | AN78: 508275.92 | AO78: 535377.14 | AP78: 563637.93 | AQ78: 593093 | AR78: 623777.4 | AS78: 655726.59 | AT78: 688976.32 | AU78: 723562.67 | AV78: 759522.03 | AW78: 796891.01 | AX78: 835706.5 | AY78: 876005.57 | AZ78: 917825.51 | BA78: 961203.73 | BB78: 1006177.8 | BC78: 1052785.4 | BD78: 1101064.3 | BE78: 1151052.2 | BF78: 1202787 | BG78: 1256306.5 | BH78: 1311648.3 | BI78: 1368850.2 | BJ78: 1427949.8 | BK78: 1488984.5 | BL78: 1551991.5 | BM78: 1617008 | BN78: 1684070.7 | BO78: 1753216.4 | BP78: 1824481.2 | BQ78: 1897901.1 | BR78: 1973511.9 | BS78: 2051348.7 | BT78: 2131446.3 | BU78: 2213839.3
A79: India | B79: =VLOOKUP(A79,'storage capacity'!$A$2:$C$195,3,FALSE) -> Country specific | C79: 6405675.7 | D79: 6977262.1 | E79: 7593626.1 | F79: 8257730.9 | G79: 8972693.4 | H79: 9741789.5 | I79: 10568459 | J79: 11456309 | K79: 12409123 | L79: 13430861 | M79: 14525668 | N79: 15697877 | O79: 16952015 | P79: 18292804 | Q79: 19725173 | R79: 21254254 | S79: 22885392 | T79: 24624148 | U79: 26476299 | V79: 28447849 | W79: 30545026 | X79: 32774290 | Y79: 35142332 | Z79: 37656080 | AA79: 40322703 | AB79: 43149609 | AC79: 46144449 | AD79: 49315123 | AE79: 52669774 | AF79: 56216796 | AG79: 59964832 | AH79: 63922774 | AI79: 68099766 | AJ79: 72505202 | AK79: 77148725 | AL79: 82040228 | AM79: 87189854 | AN79: 92607991 | AO79: 98305272 | AP79: 1.0429257e+08 | AQ79: 1.1058102e+08 | AR79: 1.1718195e+08 | AS79: 1.2410696e+08 | AT79: 1.3136788e+08 | AU79: 1.3897674e+08 | AV79: 1.4694581e+08 | AW79: 1.5528757e+08 | AX79: 1.6401473e+08 | AY79: 1.7314017e+08 | AZ79: 1.82677e+08 | BA79: 1.9263852e+08 | BB79: 2.030382e+08 | BC79: 2.1388969e+08 | BD79: 2.2520684e+08 | BE79: 2.3700363e+08 | BF79: 2.4929422e+08 | BG79: 2.6209289e+08 | BH79: 2.7541408e+08 | BI79: 2.8927236e+08 | BJ79: 3.036824e+08 | BK79: 3.1865899e+08 | BL79: 3.3421703e+08 | BM79: 3.5037149e+08 | BN79: 3.6713743e+08 | BO79: 3.8452997e+08 | BP79: 4.0256428e+08 | BQ79: 4.212556e+08 | BR79: 4.4061917e+08 | BS79: 4.6067028e+08 | BT79: 4.8142421e+08 | BU79: 5.0289626e+08
A80: Indonesia | B80: =VLOOKUP(A80,'storage capacity'!$A$2:$C$195,3,FALSE) -> Country specific | C80: 2062571.3 | D80: 2209246.4 | E80: 2364780.9 | F80: 2529600.4 | G80: 2704144.4 | H80: 2888866.2 | I80: 3084233 | J80: 3290726.3 | K80: 3508841.3 | L80: 3739087.6 | M80: 3981988.9 | N80: 4238082.9 | O80: 4507921.4 | P80: 4792070.4 | Q80: 5091109.6 | R80: 5405632.8 | S80: 5736247.3 | T80: 6083574.2 | U80: 6448247.9 | V80: 6830916.4 | W80: 7232240.4 | X80: 7652893.5 | Y80: 8093562.2 | Z80: 8554945 | AA80: 9037752.7 | AB80: 9542707.5 | AC80: 10070543 | AD80: 10622005 | AE80: 11197848 | AF80: 11798839 | AG80: 12425752 | AH80: 13079373 | AI80: 13760495 | AJ80: 14469922 | AK80: 15208464 | AL80: 15976938 | AM80: 16776170 | AN80: 17606991 | AO80: 18470237 | AP80: 19366752 | AQ80: 20297381 | AR80: 21262977 | AS80: 22264393 | AT80: 23302486 | AU80: 24378116 | AV80: 25492145 | AW80: 26645432 | AX80: 27838841 | AY80: 29073231 | AZ80: 30349465 | BA80: 31668399 | BB80: 33030888 | BC80: 34437786 | BD80: 35889941 | BE80: 37388195 | BF80: 38933387 | BG80: 40526348 | BH80: 42167905 | BI80: 43858873 | BJ80: 45600063 | BK80: 47392275 | BL80: 49236300 | BM80: 51132917 | BN80: 53082897 | BO80: 55086996 | BP80: 57145961 | BQ80: 59260524 | BR80: 61431404 | BS80: 63659305 | BT80: 65944917 | BU80: 68288915
A81: Iran | B81: =VLOOKUP(A81,'storage capacity'!$A$2:$C$195,3,FALSE) -> Country specific | C81: 658182.33 | D81: 702711.66 | E81: 749778.19 | F81: 799494.98 | G81: 851978.29 | H81: 907347.61 | I81: 965725.66 | J81: 1027238.4 | K81: 1092014.9 | L81: 1160187.5 | M81: 1231891.7 | N81: 1307266.2 | O81: 1386452.7 | P81: 1469596 | Q81: 1556844 | R81: 1648347.5 | S81: 1744260.3 | T81: 1844739 | U81: 1949943.3 | V81: 2060035.2 | W81: 2175179.7 | X81: 2295544.3 | Y81: 2421299.1 | Z81: 2552616.6 | AA81: 2689671.6 | AB81: 2832641.3 | AC81: 2981704.8 | AD81: 3137043.5 | AE81: 3298840.5 | AF81: 3467281.1 | AG81: 3642551.9 | AH81: 3824841.3 | AI81: 4014339.2 | AJ81: 4211236.7 | AK81: 4415726.2 | AL81: 4628001.1 | AM81: 4848255.7 | AN81: 5076685.4 | AO81: 5313485.7 | AP81: 5558853.1 | AQ81: 5812984.1 | AR81: 6076075.6 | AS81: 6348324.4 | AT81: 6629927.3 | AU81: 6921080.8 | AV81: 7221981 | AW81: 7532823.2 | AX81: 7853802.2 | AY81: 8185111.7 | AZ81: 8526944.6 | BA81: 8879492.3 | BB81: 9242944.9 | BC81: 9617490.9 | BD81: 10003317 | BE81: 10400609 | BF81: 10809548 | BG81: 11230317 | BH81: 11663092 | BI81: 12108051 | BJ81: 12565366 | BK81: 13035208 | BL81: 13517743 | BM81: 14013138 | BN81: 14521551 | BO81: 15043142 | BP81: 15578065 | BQ81: 16126470 | BR81: 16688503 | BS81: 17264308 | BT81: 17854023 | BU81: 18457783
A82: Iraq | B82: =VLOOKUP(A82,'storage capacity'!$A$2:$C$195,3,FALSE) -> Middle east | C82: 357920.53 | D82: 376963.45 | E82: 396818.97 | F82: 417511.32 | G82: 439064.96 | H82: 461504.63 | I82: 484855.28 | J82: 509142.07 | K82: 534390.37 | L82: 560625.73 | M82: 587873.86 | N82: 616160.6 | O82: 645511.94 | P82: 675953.97 | Q82: 707512.84 | R82: 740214.81 | S82: 774086.17 | T82: 809153.22 | U82: 845442.3 | V82: 882979.71 | W82: 921791.74 | X82: 961904.59 | Y82: 1003344.4 | Z82: 1046137.3 | AA82: 1090309.1 | AB82: 1135885.6 | AC82: 1182892.5 | AD82: 1231355.1 | AE82: 1281298.8 | AF82: 1332748.5 | AG82: 1385728.9 | AH82: 1440264.6 | AI82: 1496379.8 | AJ82: 1554098.3 | AK82: 1613443.6 | AL82: 1674439.1 | AM82: 1737107.4 | AN82: 1801471 | AO82: 1867552 | AP82: 1935371.8 | AQ82: 2004951.8 | AR82: 2076312.4 | AS82: 2149473.9 | AT82: 2224455.9 | AU82: 2301277.6 | AV82: 2379957.6 | AW82: 2460514 | AX82: 2542964.2 | AY82: 2627325.1 | AZ82: 2713613 | BA82: 2801843.6 | BB82: 2892032 | BC82: 2984192.5 | BD82: 3078338.9 | BE82: 3174484.4 | BF82: 3272641.2 | BG82: 3372821.2 | BH82: 3475035.4 | BI82: 3579294 | BJ82: 3685606.8 | BK82: 3793982.6 | BL82: 3904429.6 | BM82: 4016955.2 | BN82: 4131566.1 | BO82: 4248268.3 | BP82: 4367066.8 | BQ82: 4487966.3 | BR82: 4610970.3 | BS82: 4736081.8 | BT82: 4863303 | BU82: 4992635.2
A83: Ireland | B83: =VLOOKUP(A83,'storage capacity'!$A$2:$C$195,3,FALSE) -> Country specific | C83: 713611.4 | D83: 742669.58 | E83: 772608.6 | F83: 803443.08 | G83: 835187.5 | H83: 867856.17 | I83: 901463.22 | J83: 936022.59 | K83: 971548.02 | L83: 1008053 | M83: 1045550.9 | N83: 1084054.7 | O83: 1123577.3 | P83: 1164131.1 | Q83: 1205728.5 | R83: 1248381.5 | S83: 1292101.6 | T83: 1336900.5 | U83: 1382789 | V83: 1429778 | W83: 1477877.8 | X83: 1527098.7 | Y83: 1577450.2 | Z83: 1628941.9 | AA83: 1681582.6 | AB83: 1735381 | AC83: 1790345.4 | AD83: 1846483.6 | AE83: 1903803.1 | AF83: 1962311 | AG83: 2022013.8 | AH83: 2082917.9 | AI83: 2145029.1 | AJ83: 2208352.8 | AK83: 2272893.9 | AL83: 2338657.1 | AM83: 2405646.3 | AN83: 2473865.3 | AO83: 2543317.4 | AP83: 2614005.2 | AQ83: 2685931.1 | AR83: 2759097.2 | AS83: 2833504.6 | AT83: 2909154.6 | AU83: 2986047.6 | AV83: 3064183.8 | AW83: 3143562.7 | AX83: 3224183.6 | AY83: 3306045.3 | AZ83: 3389146 | BA83: 3473483.7 | BB83: 3559055.7 | BC83: 3645859 | BD83: 3733890.2 | BE83: 3823145.4 | BF83: 3913620.3 | BG83: 4005310.1 | BH83: 4098209.7 | BI83: 4192313.4 | BJ83: 4287615.4 | BK83: 4384109.1 | BL83: 4481787.7 | BM83: 4580644.1 | BN83: 4680670.7 | BO83: 4781859.4 | BP83: 4884201.9 | BQ83: 4987689.4 | BR83: 5092312.8 | BS83: 5198062.7 | BT83: 5304929.1 | BU83: 5412902
A84: Israel | B84: =VLOOKUP(A84,'storage capacity'!$A$2:$C$195,3,FALSE) -> Middle east | C84: 684386.6 | D84: 715123.29 | E84: 746919.22 | F84: 779796.78 | G84: 813778.28 | H84: 848885.99 | I84: 885142.07 | J84: 922568.61 | K84: 961187.57 | L84: 1001020.8 | M84: 1042089.9 | N84: 1084416.4 | O84: 1128021.7 | P84: 1172926.7 | Q84: 1219152.5 | R84: 1266719.5 | S84: 1315648.3 | T84: 1365958.7 | U84: 1417670.8 | V84: 1470803.8 | W84: 1525376.9 | X84: 1581409 | Y84: 1638918.4 | Z84: 1697923.1 | AA84: 1758440.9 | AB84: 1820489 | AC84: 1884084 | AD84: 1949242.5 | AE84: 2015980.3 | AF84: 2084312.7 | AG84: 2154254.9 | AH84: 2225821.2 | AI84: 2299025.5 | AJ84: 2373881.4 | AK84: 2450401.5 | AL84: 2528598.4 | AM84: 2608483.8 | AN84: 2690068.8 | AO84: 2773364.3 | AP84: 2858380.1 | AQ84: 2945125.8 | AR84: 3033610.3 | AS84: 3123841.8 | AT84: 3215828.1 | AU84: 3309576 | AV84: 3405092.1 | AW84: 3502382.1 | AX84: 3601451.1 | AY84: 3702303.7 | AZ84: 3804943.8 | BA84: 3909374.5 | BB84: 4015598.5 | BC84: 4123617.7 | BD84: 4233433.3 | BE84: 4345045.9 | BF84: 4458455.7 | BG84: 4573661.9 | BH84: 4690663.1 | BI84: 4809457.5 | BJ84: 4930042.4 | BK84: 5052414.5 | BL84: 5176570.1 | BM84: 5302504.5 | BN84: 5430212.7 | BO84: 5559688.8 | BP84: 5690926.5 | BQ84: 5823918.7 | BR84: 5958657.8 | BS84: 6095135.6 | BT84: 6233343.3 | BU84: 6373271.4
A85: Italy | B85: =VLOOKUP(A85,'storage capacity'!$A$2:$C$195,3,FALSE) -> Country specific | C85: 2855608.4 | D85: 2941771.8 | E85: 3029647.3 | F85: 3119242.9 | G85: 3210565.6 | H85: 3303622 | I85: 3398418.1 | J85: 3494959.1 | K85: 3593249.8 | L85: 3693294.3 | M85: 3795095.9 | N85: 3898657.5 | O85: 4003981.2 | P85: 4111068.6 | Q85: 4219920.5 | R85: 4330537.3 | S85: 4442918.5 | T85: 4557063.1 | U85: 4672969.5 | V85: 4790635.4 | W85: 4910057.8 | X85: 5031233.2 | Y85: 5154157.4 | Z85: 5278825.7 | AA85: 5405232.6 | AB85: 5533372.1 | AC85: 5663237.6 | AD85: 5794821.8 | AE85: 5928117 | AF85: 6063114.6 | AG85: 6199805.8 | AH85: 6338180.9 | AI85: 6478229.7 | AJ85: 6619941.7 | AK85: 6763305.5 | AL85: 6908309.4 | AM85: 7054941 | AN85: 7203187.5 | AO85: 7353035.5 | AP85: 7504471.1 | AQ85: 7657480 | AR85: 7812047.3 | AS85: 7968157.7 | AT85: 8125795.4 | AU85: 8284944.2 | AV85: 8445587.3 | AW85: 8607707.7 | AX85: 8771287.8 | AY85: 8936309.6 | AZ85: 9102754.9 | BA85: 9270604.9 | BB85: 9439840.6 | BC85: 9610442.4 | BD85: 9782390.5 | BE85: 9955664.9 | BF85: 10130245 | BG85: 10306110 | BH85: 10483239 | BI85: 10661611 | BJ85: 10841203 | BK85: 11021995 | BL85: 11203963 | BM85: 11387086 | BN85: 11571340 | BO85: 11756704 | BP85: 11943154 | BQ85: 12130667 | BR85: 12319219 | BS85: 12508787 | BT85: 12699347 | BU85: 12890876
A86: Jamaica | B86: =VLOOKUP(A86,'storage capacity'!$A$2:$C$195,3,FALSE) -> Other latin america | C86: 26850.133 | D86: 28141.381 | E86: 29481.193 | F86: 30870.758 | G86: 32311.267 | H86: 33803.917 | I86: 35349.905 | J86: 36950.431 | K86: 38606.693 | L86: 40319.891 | M86: 42091.22 | N86: 43921.876 | O86: 45813.049 | P86: 47765.925 | Q86: 49781.686 | R86: 51861.505 | S86: 54006.549 | T86: 56217.977 | U86: 58496.937 | V86: 60844.568 | W86: 63261.997 | X86: 65750.339 | Y86: 68310.695 | Z86: 70944.152 | AA86: 73651.782 | AB86: 76434.64 | AC86: 79293.766 | AD86: 82230.181 | AE86: 85244.885 | AF86: 88338.861 | AG86: 91513.072 | AH86: 94768.455 | AI86: 98105.931 | AJ86: 101526.39 | AK86: 105030.71 | AL86: 108619.73 | AM86: 112294.28 | AN86: 116055.15 | AO86: 119903.1 | AP86: 123838.88 | AQ86: 127863.2 | AR86: 131976.75 | AS86: 136180.18 | AT86: 140474.11 | AU86: 144859.15 | AV86: 149335.84 | AW86: 153904.74 | AX86: 158566.33 | AY86: 163321.09 | AZ86: 168169.45 | BA86: 173111.81 | BB86: 178148.55 | BC86: 183280.01 | BD86: 188506.48 | BE86: 193828.23 | BF86: 199245.51 | BG86: 204758.5 | BH86: 210367.38 | BI86: 216072.27 | BJ86: 221873.28 | BK86: 227770.47 | BL86: 233763.85 | BM86: 239853.43 | BN86: 246039.17 | BO86: 252320.98 | BP86: 258698.75 | BQ86: 265172.34 | BR86: 271741.57 | BS86: 278406.22 | BT86: 285166.04 | BU86: 292020.76
...

Sheet lat lon
A1: Country | B1: Grouping | D1: Lat | E1: Lon
A2: ='storage capacity'!A2 -> Afghanistan | B2: ='storage capacity'!C2 -> Middle east | C2: #VALUE! | D2: 34.532778 | E2: 69.165833
A3: ='storage capacity'!A3 -> Albania | B3: ='storage capacity'!C3 -> Other eurasia | C3: #VALUE! | D3: 41.328889 | E3: 19.817778
A4: ='storage capacity'!A4 -> Algeria | B4: ='storage capacity'!C4 -> Middle east | C4: #VALUE! | D4: 36.776389 | E4: 3.0586111
A5: ='storage capacity'!A5 -> Andorra | B5: ='storage capacity'!C5 -> Other eurasia | C5: #VALUE! | D5: #VALUE! | E5: #VALUE!
A6: ='storage capacity'!A6 -> Angola | B6: ='storage capacity'!C6 -> Sub-saharan africa | C6: #VALUE! | D6: -8.8383333 | E6: 13.234444
A7: ='storage capacity'!A7 -> Antigua & Barbuda | B7: ='storage capacity'!C7 -> Other latin america | C7: #VALUE! | D7: 17.121111 | E7: -61.844722
A8: ='storage capacity'!A8 -> Argentina | B8: ='storage capacity'!C8 -> Country specific | C8: #VALUE! | D8: -34.6084 | E8: -58.4441
A9: ='storage capacity'!A9 -> Armenia | B9: ='storage capacity'!C9 -> Other eurasia | C9: #VALUE! | D9: #VALUE! | E9: #VALUE!
